Workbook
Name DataIDs: '#Data'!$A:$A
Name SourceIDs: '#Data'!$G:$G
Name DataIcons: '#Data'!$D:$D

Sheet Settings
A1: key | B1: value
A2: access_level | B2: 5
A3: energy_max_capacity | B3: 100
A4: energy_refill_time | B4: 120
A5: energy_refill_step | B5: 1
A6: bonus_order_time_min | B6: 1000
A7: bonus_order_time_max | B7: 1200
A8: bonus_order_queue_min | B8: 9
A9: bonus_order_queue_max | B9: 12
A10: ads_cooldawn | B10: 10800

Sheet Objects
A1: {=IF(ROW(I1:I459) < 2, "object_id", IF(ISBLANK(I1:I459),, VLOOKUP(I1:I459, {SourceIDs, DataIDs}, 2, FALSE)))} -> object_id | B1: object_type | C1: {=IF(ROW(I1:I459) < 2,"object_name", IF(ISBLANK(I1:I459),,VLOOKUP(I1:I459, {SourceIDs, '#Data'!$B$1:$B459}, 2, FALSE)))} -> object_name | D1: {=IF(ROW(I1:I459) < 2, "object_icon", IF(ISBLANK(I1:I459),,VLOOKUP(I1:I459, {SourceIDs, DataIcons}, 2, FALSE)))} -> object_icon | E1: base_cost | F1: deletable | G1: bubble_probability | H1: ads | I1: =IFERROR(__xludf.DUMMYFUNCTION(" FILTER(SourceIDs, SourceIDs & """" <> """")"),"# analog in TT") -> # analog in TT
A2: generator_OR_01 | B2: interactable | C2: Генератор обычных специй ур1 | E2: 0 | F2: FALSE | G2: 0 | I2: =IFERROR(__xludf.DUMMYFUNCTION("""COMPUTED_VALUE"""),"generator_OR_01") -> generator_OR_01
A3: generator_OR_02 | B3: interactable | C3: Генератор обычных специй ур2 | E3: 0 | F3: FALSE | G3: 0 | I3: =IFERROR(__xludf.DUMMYFUNCTION("""COMPUTED_VALUE"""),"generator_OR_02") -> generator_OR_02
A4: generator_OR_03 | B4: interactable | C4: Генератор обычных специй ур3 | E4: 0 | F4: FALSE | G4: 0 | I4: =IFERROR(__xludf.DUMMYFUNCTION("""COMPUTED_VALUE"""),"generator_OR_03") -> generator_OR_03
A5: generator_OR_04 | B5: interactable | C5: Генератор обычных специй ур4 | E5: 0 | F5: FALSE | G5: 0 | I5: =IFERROR(__xludf.DUMMYFUNCTION("""COMPUTED_VALUE"""),"generator_OR_04") -> generator_OR_04
A6: generator_OR_05 | B6: interactable | C6: Генератор обычных специй ур5 | E6: 0 | F6: FALSE | G6: 0 | I6: =IFERROR(__xludf.DUMMYFUNCTION("""COMPUTED_VALUE"""),"generator_OR_05") -> generator_OR_05
A7: generator_OR_06 | B7: interactable | C7: Генератор обычных специй ур6 | E7: 0 | F7: FALSE | G7: 0 | I7: =IFERROR(__xludf.DUMMYFUNCTION("""COMPUTED_VALUE"""),"generator_OR_06") -> generator_OR_06
A8: chain_A_01 | B8: simple | C8: роза ч1 | E8: 0 | F8: TRUE | G8: 0 | I8: =IFERROR(__xludf.DUMMYFUNCTION("""COMPUTED_VALUE"""),"chain_A_01") -> chain_A_01
A9: chain_A_02 | B9: simple | C9: роза ч2 | E9: 0 | F9: TRUE | G9: 0 | I9: =IFERROR(__xludf.DUMMYFUNCTION("""COMPUTED_VALUE"""),"chain_A_02") -> chain_A_02
A10: chain_A_03 | B10: simple | C10: роза | E10: 2 | F10: TRUE | G10: 0 | I10: =IFERROR(__xludf.DUMMYFUNCTION("""COMPUTED_VALUE"""),"chain_A_03") -> chain_A_03
A11: chain_B_01 | B11: simple | C11: анис ч1 | E11: 2 | F11: TRUE | G11: 0 | I11: =IFERROR(__xludf.DUMMYFUNCTION("""COMPUTED_VALUE"""),"chain_B_01") -> chain_B_01
A12: chain_B_02 | B12: simple | C12: анис ч2 | E12: 2 | F12: TRUE | G12: 0 | I12: =IFERROR(__xludf.DUMMYFUNCTION("""COMPUTED_VALUE"""),"chain_B_02") -> chain_B_02
A13: chain_B_03 | B13: simple | C13: анис ч3 | E13: 3 | F13: TRUE | G13: 0 | I13: =IFERROR(__xludf.DUMMYFUNCTION("""COMPUTED_VALUE"""),"chain_B_03") -> chain_B_03
A14: chain_B_04 | B14: simple | C14: анис | E14: 4 | F14: FALSE | G14: 0 | I14: =IFERROR(__xludf.DUMMYFUNCTION("""COMPUTED_VALUE"""),"chain_B_04") -> chain_B_04
A15: generator_RD_01 | B15: interactable | C15: Генератор розовых специй ур1 | E15: 0 | F15: FALSE | G15: 0 | I15: =IFERROR(__xludf.DUMMYFUNCTION("""COMPUTED_VALUE"""),"generator_RD_01") -> generator_RD_01
A16: generator_RD_02 | B16: interactable | C16: Генератор розовых специй ур2 | E16: 0 | F16: FALSE | G16: 0 | I16: =IFERROR(__xludf.DUMMYFUNCTION("""COMPUTED_VALUE"""),"generator_RD_02") -> generator_RD_02
A17: generator_RD_03 | B17: interactable | C17: Генератор розовых специй ур3 | E17: 0 | F17: FALSE | G17: 0 | I17: =IFERROR(__xludf.DUMMYFUNCTION("""COMPUTED_VALUE"""),"generator_RD_03") -> generator_RD_03
A18: generator_RD_04 | B18: interactable | C18: Генератор розовых специй ур4 | E18: 0 | F18: FALSE | G18: 0 | I18: =IFERROR(__xludf.DUMMYFUNCTION("""COMPUTED_VALUE"""),"generator_RD_04") -> generator_RD_04
A19: generator_RD_05 | B19: interactable | C19: Генератор розовых специй ур5 | E19: 0 | F19: FALSE | G19: 0 | I19: =IFERROR(__xludf.DUMMYFUNCTION("""COMPUTED_VALUE"""),"generator_RD_05") -> generator_RD_05
A20: generator_RD_06 | B20: interactable | C20: Генератор розовых специй ур6 | E20: 0 | F20: FALSE | G20: 0 | I20: =IFERROR(__xludf.DUMMYFUNCTION("""COMPUTED_VALUE"""),"generator_RD_06") -> generator_RD_06
A21: chain_C_01 | B21: simple | C21: бадьян ч1 | E21: 0 | F21: TRUE | G21: 0 | I21: =IFERROR(__xludf.DUMMYFUNCTION("""COMPUTED_VALUE"""),"chain_C_01") -> chain_C_01
A22: chain_C_02 | B22: simple | C22: бадьян ч2 | E22: 1 | F22: TRUE | G22: 0 | I22: =IFERROR(__xludf.DUMMYFUNCTION("""COMPUTED_VALUE"""),"chain_C_02") -> chain_C_02
A23: chain_C_03 | B23: simple | C23: бадьян ч3 | E23: 2 | F23: TRUE | G23: 0 | I23: =IFERROR(__xludf.DUMMYFUNCTION("""COMPUTED_VALUE"""),"chain_C_03") -> chain_C_03
A24: chain_C_04 | B24: simple | C24: бадьян ч4 | E24: 3 | F24: TRUE | G24: 60 | H24: 1 | I24: =IFERROR(__xludf.DUMMYFUNCTION("""COMPUTED_VALUE"""),"chain_C_04") -> chain_C_04
A25: chain_C_05 | B25: simple | C25: бадьян | E25: 6 | F25: TRUE | G25: 80 | H25: 1 | I25: =IFERROR(__xludf.DUMMYFUNCTION("""COMPUTED_VALUE"""),"chain_C_05") -> chain_C_05
A26: chain_D_01 | B26: simple | C26: мускат ч1 | E26: 2 | F26: TRUE | G26: 0 | I26: =IFERROR(__xludf.DUMMYFUNCTION("""COMPUTED_VALUE"""),"chain_D_01") -> chain_D_01
A27: chain_D_02 | B27: simple | C27: мускат ч2 | E27: 2 | F27: TRUE | G27: 0 | I27: =IFERROR(__xludf.DUMMYFUNCTION("""COMPUTED_VALUE"""),"chain_D_02") -> chain_D_02
A28: chain_D_03 | B28: simple | C28: мускат ч3 | E28: 3 | F28: TRUE | G28: 0 | I28: =IFERROR(__xludf.DUMMYFUNCTION("""COMPUTED_VALUE"""),"chain_D_03") -> chain_D_03
A29: chain_D_04 | B29: simple | C29: мускат ч4 | E29: 4 | F29: TRUE | G29: 0 | I29: =IFERROR(__xludf.DUMMYFUNCTION("""COMPUTED_VALUE"""),"chain_D_04") -> chain_D_04
A30: chain_D_05 | B30: simple | C30: мускат ч5 | E30: 6 | F30: TRUE | G30: 60 | H30: 1 | I30: =IFERROR(__xludf.DUMMYFUNCTION("""COMPUTED_VALUE"""),"chain_D_05") -> chain_D_05
A31: chain_D_06 | B31: simple | C31: мускат | E31: 10 | F31: FALSE | G31: 80 | H31: 1 | I31: =IFERROR(__xludf.DUMMYFUNCTION("""COMPUTED_VALUE"""),"chain_D_06") -> chain_D_06
A32: generator_BL_01 | B32: interactable | C32: генератор синих специй ур1 | E32: 0 | F32: FALSE | G32: 0 | I32: =IFERROR(__xludf.DUMMYFUNCTION("""COMPUTED_VALUE"""),"generator_BL_01") -> generator_BL_01
A33: generator_BL_02 | B33: interactable | C33: генератор синих специй ур2 | E33: 0 | F33: FALSE | G33: 0 | I33: =IFERROR(__xludf.DUMMYFUNCTION("""COMPUTED_VALUE"""),"generator_BL_02") -> generator_BL_02
A34: generator_BL_03 | B34: interactable | C34: генератор синих специй ур3 | E34: 0 | F34: FALSE | G34: 0 | I34: =IFERROR(__xludf.DUMMYFUNCTION("""COMPUTED_VALUE"""),"generator_BL_03") -> generator_BL_03
A35: generator_BL_04 | B35: interactable | C35: генератор синих специй ур4 | E35: 0 | F35: FALSE | G35: 0 | I35: =IFERROR(__xludf.DUMMYFUNCTION("""COMPUTED_VALUE"""),"generator_BL_04") -> generator_BL_04
A36: generator_BL_05 | B36: interactable | C36: генератор синих специй ур5 | E36: 0 | F36: FALSE | G36: 0 | I36: =IFERROR(__xludf.DUMMYFUNCTION("""COMPUTED_VALUE"""),"generator_BL_05") -> generator_BL_05
A37: generator_BL_06 | B37: interactable | C37: генератор синих специй | E37: 0 | F37: FALSE | G37: 0 | I37: =IFERROR(__xludf.DUMMYFUNCTION("""COMPUTED_VALUE"""),"generator_BL_06") -> generator_BL_06
A38: chain_E_01 | B38: simple | C38: женьшень 1 | E38: 0 | F38: TRUE | G38: 0 | I38: =IFERROR(__xludf.DUMMYFUNCTION("""COMPUTED_VALUE"""),"chain_E_01") -> chain_E_01
A39: chain_E_02 | B39: simple | C39: женьшень 2 | E39: 1 | F39: TRUE | G39: 0 | I39: =IFERROR(__xludf.DUMMYFUNCTION("""COMPUTED_VALUE"""),"chain_E_02") -> chain_E_02
A40: chain_E_03 | B40: simple | C40: женьшень 3 | E40: 2 | F40: TRUE | G40: 0 | I40: =IFERROR(__xludf.DUMMYFUNCTION("""COMPUTED_VALUE"""),"chain_E_03") -> chain_E_03
...

Sheet Interactables
A1: # Object ID | B1: object_id | C1: cooldown_cycle | D1: reload_time | E1: skip_cost | F1: free_skip_time | G1: produced_objects | H1: count_per_cycle | I1: uses | J1: # Spawns After Used
A2: item_cyberm-setup_00 | B2: generator_OR_01 | C2: 15 | D2: 300 | E2: 50 | F2: 30 | G2: chain_A_01 | H2: 1
A4: item_cyberm-setup_01 | B4: generator_OR_02 | C4: 15 | D4: 300 | E4: 50 | F4: 30 | G4: chain_A_01 | H4: 3
G5: chain_A_02 | H5: 1
G6: chain_B_01 | H6: 3
G7: chain_B_02 | H7: 2
G8: chain_B_03 | H8: 1
B10: generator_OR_03 | C10: 15 | D10: 300 | E10: 50 | F10: 30 | G10: chain_A_01 | H10: 3
G11: chain_A_02 | H11: 1
G12: chain_B_01 | H12: 1
A13: item_cyberm-seagull-shopping_00 | G13: chain_B_02 | H13: 3
G14: chain_B_03 | H14: 2
B16: generator_OR_04 | C16: 15 | D16: 300 | E16: 50 | F16: 30 | G16: chain_A_01 | H16: 3
G17: chain_A_02 | H17: 1
G18: chain_B_01 | H18: 1
G19: chain_B_02 | H19: 1
A20: item_cyberm-antique-active_00 | G20: chain_B_03 | H20: 4
B22: generator_OR_05 | C22: 15 | D22: 300 | E22: 50 | F22: 30 | G22: chain_A_01 | H22: 1
G23: chain_A_02 | H23: 2
G24: chain_B_01 | H24: 1
A25: item_cyberm-antique-active_01 | G25: chain_B_02 | H25: 3
G26: chain_B_03 | H26: 3
B28: generator_OR_06 | C28: 15 | D28: 300 | E28: 50 | F28: 30 | G28: chain_A_01 | H28: 1
G29: chain_A_02 | H29: 2
G30: chain_B_01 | H30: 1
G31: chain_B_02 | H31: 1
G32: chain_B_03 | H32: 5
B34: generator_RD_01 | C34: 15 | D34: 300 | E34: 50 | F34: 30 | G34: chain_C_01 | H34: 1
B36: generator_RD_02 | C36: 15 | D36: 300 | E36: 50 | F36: 30 | G36: chain_C_01 | H36: 1
G37: chain_C_02 | H37: 2
G38: chain_C_03 | H38: 1
G39: chain_D_01 | H39: 1
G40: chain_D_02 | H40: 3
G41: chain_D_03 | H41: 2
B43: generator_RD_03 | C43: 15 | D43: 300 | E43: 50 | F43: 30 | G43: chain_C_01 | H43: 1
G44: chain_C_02 | H44: 1
G45: chain_C_03 | H45: 1
G46: chain_C_04 | H46: 1
G47: chain_D_01 | H47: 1
G48: chain_D_02 | H48: 4
...

Sheet Chains
A1: chain_id | B1: {=DataIDs} -> object_id | C1: object_level | D1: item_name | E1: item_value
A2: =IFS( ISBLANK(B2),, ISBLANK(B1), LEFT(B2, LEN(B2) - 3), LEFT(B2, LEN(B2)-1) = LEFT(B1, LEN(B1)-1),, TRUE, LEFT(B2, LEN(B2) - 3) ) -> generator_OR | B2: generator_OR_01 | C2: =IFS( ISBLANK(B2),, NOT(ISBLANK(A2)), 1, TRUE, C1 + 1 ) -> 1
A3: =IFS( ISBLANK(B3),, ISBLANK(B2), LEFT(B3, LEN(B3) - 3), LEFT(B3, LEN(B3)-1) = LEFT(B2, LEN(B2)-1),, TRUE, LEFT(B3, LEN(B3) - 3) ) | B3: generator_OR_02 | C3: =IFS( ISBLANK(B3),, NOT(ISBLANK(A3)), 1, TRUE, C2 + 1 ) -> 2
A4: =IFS( ISBLANK(B4),, ISBLANK(B3), LEFT(B4, LEN(B4) - 3), LEFT(B4, LEN(B4)-1) = LEFT(B3, LEN(B3)-1),, TRUE, LEFT(B4, LEN(B4) - 3) ) | B4: generator_OR_03 | C4: =IFS( ISBLANK(B4),, NOT(ISBLANK(A4)), 1, TRUE, C3 + 1 ) -> 3
A5: =IFS( ISBLANK(B5),, ISBLANK(B4), LEFT(B5, LEN(B5) - 3), LEFT(B5, LEN(B5)-1) = LEFT(B4, LEN(B4)-1),, TRUE, LEFT(B5, LEN(B5) - 3) ) | B5: generator_OR_04 | C5: =IFS( ISBLANK(B5),, NOT(ISBLANK(A5)), 1, TRUE, C4 + 1 ) -> 4
A6: =IFS( ISBLANK(B6),, ISBLANK(B5), LEFT(B6, LEN(B6) - 3), LEFT(B6, LEN(B6)-1) = LEFT(B5, LEN(B5)-1),, TRUE, LEFT(B6, LEN(B6) - 3) ) | B6: generator_OR_05 | C6: =IFS( ISBLANK(B6),, NOT(ISBLANK(A6)), 1, TRUE, C5 + 1 ) -> 5
A7: =IFS( ISBLANK(B7),, ISBLANK(B6), LEFT(B7, LEN(B7) - 3), LEFT(B7, LEN(B7)-1) = LEFT(B6, LEN(B6)-1),, TRUE, LEFT(B7, LEN(B7) - 3) ) | B7: generator_OR_06 | C7: =IFS( ISBLANK(B7),, NOT(ISBLANK(A7)), 1, TRUE, C6 + 1 ) -> 6
A8: =IFS( ISBLANK(B8),, ISBLANK(B7), LEFT(B8, LEN(B8) - 3), LEFT(B8, LEN(B8)-1) = LEFT(B7, LEN(B7)-1),, TRUE, LEFT(B8, LEN(B8) - 3) ) | C8: =IFS( ISBLANK(B8),, NOT(ISBLANK(A8)), 1, TRUE, C7 + 1 )
A9: =IFS( ISBLANK(B9),, ISBLANK(B8), LEFT(B9, LEN(B9) - 3), LEFT(B9, LEN(B9)-1) = LEFT(B8, LEN(B8)-1),, TRUE, LEFT(B9, LEN(B9) - 3) ) -> chain_A | B9: chain_A_01 | C9: =IFS( ISBLANK(B9),, NOT(ISBLANK(A9)), 1, TRUE, C8 + 1 ) -> 1
A10: =IFS( ISBLANK(B10),, ISBLANK(B9), LEFT(B10, LEN(B10) - 3), LEFT(B10, LEN(B10)-1) = LEFT(B9, LEN(B9)-1),, TRUE, LEFT(B10, LEN(B10) - 3) ) | B10: chain_A_02 | C10: =IFS( ISBLANK(B10),, NOT(ISBLANK(A10)), 1, TRUE, C9 + 1 ) -> 2
A11: =IFS( ISBLANK(B11),, ISBLANK(B10), LEFT(B11, LEN(B11) - 3), LEFT(B11, LEN(B11)-1) = LEFT(B10, LEN(B10)-1),, TRUE, LEFT(B11, LEN(B11) - 3) ) | B11: chain_A_03 | C11: =IFS( ISBLANK(B11),, NOT(ISBLANK(A11)), 1, TRUE, C10 + 1 ) -> 3
A12: =IFS( ISBLANK(B12),, ISBLANK(B11), LEFT(B12, LEN(B12) - 3), LEFT(B12, LEN(B12)-1) = LEFT(B11, LEN(B11)-1),, TRUE, LEFT(B12, LEN(B12) - 3) ) | C12: =IFS( ISBLANK(B12),, NOT(ISBLANK(A12)), 1, TRUE, C11 + 1 )
A13: =IFS( ISBLANK(B13),, ISBLANK(B12), LEFT(B13, LEN(B13) - 3), LEFT(B13, LEN(B13)-1) = LEFT(B12, LEN(B12)-1),, TRUE, LEFT(B13, LEN(B13) - 3) ) -> chain_B | B13: chain_B_01 | C13: =IFS( ISBLANK(B13),, NOT(ISBLANK(A13)), 1, TRUE, C12 + 1 ) -> 1
A14: =IFS( ISBLANK(B14),, ISBLANK(B13), LEFT(B14, LEN(B14) - 3), LEFT(B14, LEN(B14)-1) = LEFT(B13, LEN(B13)-1),, TRUE, LEFT(B14, LEN(B14) - 3) ) | B14: chain_B_02 | C14: =IFS( ISBLANK(B14),, NOT(ISBLANK(A14)), 1, TRUE, C13 + 1 ) -> 2
A15: =IFS( ISBLANK(B15),, ISBLANK(B14), LEFT(B15, LEN(B15) - 3), LEFT(B15, LEN(B15)-1) = LEFT(B14, LEN(B14)-1),, TRUE, LEFT(B15, LEN(B15) - 3) ) | B15: chain_B_03 | C15: =IFS( ISBLANK(B15),, NOT(ISBLANK(A15)), 1, TRUE, C14 + 1 ) -> 3
A16: =IFS( ISBLANK(B16),, ISBLANK(B15), LEFT(B16, LEN(B16) - 3), LEFT(B16, LEN(B16)-1) = LEFT(B15, LEN(B15)-1),, TRUE, LEFT(B16, LEN(B16) - 3) ) | B16: chain_B_04 | C16: =IFS( ISBLANK(B16),, NOT(ISBLANK(A16)), 1, TRUE, C15 + 1 ) -> 4
A17: =IFS( ISBLANK(B17),, ISBLANK(B16), LEFT(B17, LEN(B17) - 3), LEFT(B17, LEN(B17)-1) = LEFT(B16, LEN(B16)-1),, TRUE, LEFT(B17, LEN(B17) - 3) ) | C17: =IFS( ISBLANK(B17),, NOT(ISBLANK(A17)), 1, TRUE, C16 + 1 )
A18: =IFS( ISBLANK(B18),, ISBLANK(B17), LEFT(B18, LEN(B18) - 3), LEFT(B18, LEN(B18)-1) = LEFT(B17, LEN(B17)-1),, TRUE, LEFT(B18, LEN(B18) - 3) ) -> generator_RD | B18: generator_RD_01 | C18: =IFS( ISBLANK(B18),, NOT(ISBLANK(A18)), 1, TRUE, C17 + 1 ) -> 1
A19: =IFS( ISBLANK(B19),, ISBLANK(B18), LEFT(B19, LEN(B19) - 3), LEFT(B19, LEN(B19)-1) = LEFT(B18, LEN(B18)-1),, TRUE, LEFT(B19, LEN(B19) - 3) ) | B19: generator_RD_02 | C19: =IFS( ISBLANK(B19),, NOT(ISBLANK(A19)), 1, TRUE, C18 + 1 ) -> 2
A20: =IFS( ISBLANK(B20),, ISBLANK(B19), LEFT(B20, LEN(B20) - 3), LEFT(B20, LEN(B20)-1) = LEFT(B19, LEN(B19)-1),, TRUE, LEFT(B20, LEN(B20) - 3) ) | B20: generator_RD_03 | C20: =IFS( ISBLANK(B20),, NOT(ISBLANK(A20)), 1, TRUE, C19 + 1 ) -> 3
A21: =IFS( ISBLANK(B21),, ISBLANK(B20), LEFT(B21, LEN(B21) - 3), LEFT(B21, LEN(B21)-1) = LEFT(B20, LEN(B20)-1),, TRUE, LEFT(B21, LEN(B21) - 3) ) | B21: generator_RD_04 | C21: =IFS( ISBLANK(B21),, NOT(ISBLANK(A21)), 1, TRUE, C20 + 1 ) -> 4
A22: =IFS( ISBLANK(B22),, ISBLANK(B21), LEFT(B22, LEN(B22) - 3), LEFT(B22, LEN(B22)-1) = LEFT(B21, LEN(B21)-1),, TRUE, LEFT(B22, LEN(B22) - 3) ) | B22: generator_RD_05 | C22: =IFS( ISBLANK(B22),, NOT(ISBLANK(A22)), 1, TRUE, C21 + 1 ) -> 5
A23: =IFS( ISBLANK(B23),, ISBLANK(B22), LEFT(B23, LEN(B23) - 3), LEFT(B23, LEN(B23)-1) = LEFT(B22, LEN(B22)-1),, TRUE, LEFT(B23, LEN(B23) - 3) ) | B23: generator_RD_06 | C23: =IFS( ISBLANK(B23),, NOT(ISBLANK(A23)), 1, TRUE, C22 + 1 ) -> 6
A24: =IFS( ISBLANK(B24),, ISBLANK(B23), LEFT(B24, LEN(B24) - 3), LEFT(B24, LEN(B24)-1) = LEFT(B23, LEN(B23)-1),, TRUE, LEFT(B24, LEN(B24) - 3) ) | C24: =IFS( ISBLANK(B24),, NOT(ISBLANK(A24)), 1, TRUE, C23 + 1 )
A25: =IFS( ISBLANK(B25),, ISBLANK(B24), LEFT(B25, LEN(B25) - 3), LEFT(B25, LEN(B25)-1) = LEFT(B24, LEN(B24)-1),, TRUE, LEFT(B25, LEN(B25) - 3) ) -> chain_C | B25: chain_C_01 | C25: =IFS( ISBLANK(B25),, NOT(ISBLANK(A25)), 1, TRUE, C24 + 1 ) -> 1
A26: =IFS( ISBLANK(B26),, ISBLANK(B25), LEFT(B26, LEN(B26) - 3), LEFT(B26, LEN(B26)-1) = LEFT(B25, LEN(B25)-1),, TRUE, LEFT(B26, LEN(B26) - 3) ) | B26: chain_C_02 | C26: =IFS( ISBLANK(B26),, NOT(ISBLANK(A26)), 1, TRUE, C25 + 1 ) -> 2
A27: =IFS( ISBLANK(B27),, ISBLANK(B26), LEFT(B27, LEN(B27) - 3), LEFT(B27, LEN(B27)-1) = LEFT(B26, LEN(B26)-1),, TRUE, LEFT(B27, LEN(B27) - 3) ) | B27: chain_C_03 | C27: =IFS( ISBLANK(B27),, NOT(ISBLANK(A27)), 1, TRUE, C26 + 1 ) -> 3
A28: =IFS( ISBLANK(B28),, ISBLANK(B27), LEFT(B28, LEN(B28) - 3), LEFT(B28, LEN(B28)-1) = LEFT(B27, LEN(B27)-1),, TRUE, LEFT(B28, LEN(B28) - 3) ) | B28: chain_C_04 | C28: =IFS( ISBLANK(B28),, NOT(ISBLANK(A28)), 1, TRUE, C27 + 1 ) -> 4
A29: =IFS( ISBLANK(B29),, ISBLANK(B28), LEFT(B29, LEN(B29) - 3), LEFT(B29, LEN(B29)-1) = LEFT(B28, LEN(B28)-1),, TRUE, LEFT(B29, LEN(B29) - 3) ) | B29: chain_C_05 | C29: =IFS( ISBLANK(B29),, NOT(ISBLANK(A29)), 1, TRUE, C28 + 1 ) -> 5
A30: =IFS( ISBLANK(B30),, ISBLANK(B29), LEFT(B30, LEN(B30) - 3), LEFT(B30, LEN(B30)-1) = LEFT(B29, LEN(B29)-1),, TRUE, LEFT(B30, LEN(B30) - 3) ) | C30: =IFS( ISBLANK(B30),, NOT(ISBLANK(A30)), 1, TRUE, C29 + 1 )
A31: =IFS( ISBLANK(B31),, ISBLANK(B30), LEFT(B31, LEN(B31) - 3), LEFT(B31, LEN(B31)-1) = LEFT(B30, LEN(B30)-1),, TRUE, LEFT(B31, LEN(B31) - 3) ) -> chain_D | B31: chain_D_01 | C31: =IFS( ISBLANK(B31),, NOT(ISBLANK(A31)), 1, TRUE, C30 + 1 ) -> 1
A32: =IFS( ISBLANK(B32),, ISBLANK(B31), LEFT(B32, LEN(B32) - 3), LEFT(B32, LEN(B32)-1) = LEFT(B31, LEN(B31)-1),, TRUE, LEFT(B32, LEN(B32) - 3) ) | B32: chain_D_02 | C32: =IFS( ISBLANK(B32),, NOT(ISBLANK(A32)), 1, TRUE, C31 + 1 ) -> 2
A33: =IFS( ISBLANK(B33),, ISBLANK(B32), LEFT(B33, LEN(B33) - 3), LEFT(B33, LEN(B33)-1) = LEFT(B32, LEN(B32)-1),, TRUE, LEFT(B33, LEN(B33) - 3) ) | B33: chain_D_03 | C33: =IFS( ISBLANK(B33),, NOT(ISBLANK(A33)), 1, TRUE, C32 + 1 ) -> 3
A34: =IFS( ISBLANK(B34),, ISBLANK(B33), LEFT(B34, LEN(B34) - 3), LEFT(B34, LEN(B34)-1) = LEFT(B33, LEN(B33)-1),, TRUE, LEFT(B34, LEN(B34) - 3) ) | B34: chain_D_04 | C34: =IFS( ISBLANK(B34),, NOT(ISBLANK(A34)), 1, TRUE, C33 + 1 ) -> 4
A35: =IFS( ISBLANK(B35),, ISBLANK(B34), LEFT(B35, LEN(B35) - 3), LEFT(B35, LEN(B35)-1) = LEFT(B34, LEN(B34)-1),, TRUE, LEFT(B35, LEN(B35) - 3) ) | B35: chain_D_05 | C35: =IFS( ISBLANK(B35),, NOT(ISBLANK(A35)), 1, TRUE, C34 + 1 ) -> 5
A36: =IFS( ISBLANK(B36),, ISBLANK(B35), LEFT(B36, LEN(B36) - 3), LEFT(B36, LEN(B36)-1) = LEFT(B35, LEN(B35)-1),, TRUE, LEFT(B36, LEN(B36) - 3) ) | B36: chain_D_06 | C36: =IFS( ISBLANK(B36),, NOT(ISBLANK(A36)), 1, TRUE, C35 + 1 ) -> 6
A37: =IFS( ISBLANK(B37),, ISBLANK(B36), LEFT(B37, LEN(B37) - 3), LEFT(B37, LEN(B37)-1) = LEFT(B36, LEN(B36)-1),, TRUE, LEFT(B37, LEN(B37) - 3) ) | C37: =IFS( ISBLANK(B37),, NOT(ISBLANK(A37)), 1, TRUE, C36 + 1 )
A38: =IFS( ISBLANK(B38),, ISBLANK(B37), LEFT(B38, LEN(B38) - 3), LEFT(B38, LEN(B38)-1) = LEFT(B37, LEN(B37)-1),, TRUE, LEFT(B38, LEN(B38) - 3) ) -> generator_BL | B38: generator_BL_01 | C38: =IFS( ISBLANK(B38),, NOT(ISBLANK(A38)), 1, TRUE, C37 + 1 ) -> 1
A39: =IFS( ISBLANK(B39),, ISBLANK(B38), LEFT(B39, LEN(B39) - 3), LEFT(B39, LEN(B39)-1) = LEFT(B38, LEN(B38)-1),, TRUE, LEFT(B39, LEN(B39) - 3) ) | B39: generator_BL_02 | C39: =IFS( ISBLANK(B39),, NOT(ISBLANK(A39)), 1, TRUE, C38 + 1 ) -> 2
A40: =IFS( ISBLANK(B40),, ISBLANK(B39), LEFT(B40, LEN(B40) - 3), LEFT(B40, LEN(B40)-1) = LEFT(B39, LEN(B39)-1),, TRUE, LEFT(B40, LEN(B40) - 3) ) | B40: generator_BL_03 | C40: =IFS( ISBLANK(B40),, NOT(ISBLANK(A40)), 1, TRUE, C39 + 1 ) -> 3
...

Sheet Spice Chain Order
A1: spice | B1: energy_reward | C1: #merge_price
A2: spice_rose | B2: 1 | C2: 4
A3: spice_anise | B3: 2 | C3: 8
A4: spice_badian | B4: 3 | C4: 12
A5: spice_muskat | B5: 4 | C5: 19
A6: spice_jenjen | B6: 5 | C6: 25
A7: spice_kalgan | B7: 8 | C7: 35
A8: spice_kardamon | B8: 10 | C8: 52
A9: spice_tapioka | B9: 12 | C9: 78
A10: spice_guarana | B10: 15 | C10: 113
A11: spice_shafran | B11: 18 | C11: 125
A12: spice_gold | B12: 20 | C12: 198

Sheet Orders Allocation
A1: player_level | B1: easy_order | C1: medium_order | D1: hard_order | E1: super_hard
A2: 5 | B2: 2 | C2: 3
A3: 7 | B3: 2 | C3: 3 | D3: 1
A4: 10 | B4: 2 | C4: 4 | D4: 1
A5: 15 | B5: 1 | C5: 4 | D5: 1 | E5: 1
A6: 20 | C6: 5 | D6: 1 | E6: 1
A7: 30 | C7: 4 | D7: 2 | E7: 1
A8: 40 | C8: 4 | D8: 2 | E8: 1
A9: 50 | C9: 4 | D9: 2 | E9: 1
A10: 60 | C10: 4 | D10: 2 | E10: 1

Sheet Orders Difficulty
A1: order_dffculty | B1: min | C1: max
A2: easy | B2: 8 | C2: 40
A3: medium | B3: 41 | C3: 70
A4: hard | B4: 71 | C4: 100
A5: super hard | B5: 101 | C5: 200

Sheet Orders Rewards
A1: weight | B1: order_type | C1: object_id
A2: 100 | B2: easy | C2: chain_N_01
A3: 90 | B3: easy | C3: chain_N_02
A4: 60 | B4: medium | C4: chain_N_03
A5: 40 | B5: medium | C5: chain_N_03
A6: 80 | B6: hard | C6: chain_O_01
A7: 60 | B7: hard | C7: chain_O_02
A8: 40 | B8: hard | C8: chain_O_03
A9: 80 | B9: super hard | C9: chain_T_01
A10: 60 | B10: super hard | C10: chain_T_02
A11: 40 | B11: super hard | C11: chain_T_03

Sheet Bonus Order
A1: bonus_order_type | B1: min_price | C1: max_price
A2: regular | B2: 100 | C2: 150
A3: hard | B3: 150 | C3: 200
A4: super_hard | B4: 200 | C4: 300

Sheet  Bonus Order Reward
A1: weight_reward | B1: bounus_order_type | C1: item_name_1 | D1: item_value_1
A2: 50 | B2: regular | C2: box1 | D2: 1
A3: 50 | B3: regular | C3: box2 | D3: 1
A4: 50 | B4: regular | C4: box2 | D4: 1
A5: 40 | B5: hard | C5: booster_bunny | D5: 300
A6: 40 | B6: hard | C6: booster_trophy | D6: 600
A7: 40 | B7: hard | C7: GameCrystal | D7: 100
A8: 30 | B8: super_hard | C8: pink_collection_box | D8: 2
A9: 30 | B9: super_hard | C9: blue_collection_box | D9: 1
A10: 30 | B10: super_hard | C10: Tickets | D10: 5

Sheet Field
A1: x_coordinate | B1: y_coordinate | C1: {=IF(ROW($A1:$A64) < 2, "#xy", LEFT($A1:$A64) & "," & LEFT($B1:$B64))} -> #xy | D1: {=IF(ROW($A1:$A64) < 2, "#col", MATCH($A1:$A64, '#Field'!$W$1:$BF$1))} -> #col | E1: {=IF(ROW($A1:$A64) < 2, "#row", MATCH($B1:$B64, '#Field'!$V$2:$V$36))} -> #row | F1: object_id | G1: locked | H1: closed | I1: required_level
A2: 1 | B2: 1 | C2: 1,1 | D2: 1 | E2: 1 | F2: =OFFSET('#Field'!$V$1, $E2, $D2) -> chain_I_01 | G2: =OFFSET('#Field'!$V$1, $E2+2, $D2) -> TRUE | H2: =OFFSET('#Field'!$V$1, $E2+3, $D2) -> TRUE | I2: =OFFSET('#Field'!$V$1, $E2+1, $D2) -> 14
A3: 1 | B3: 2 | C3: 1,2 | D3: 1 | E3: 5 | F3: =OFFSET('#Field'!$V$1, $E3, $D3) -> chain_D_02 | G3: =OFFSET('#Field'!$V$1, $E3+2, $D3) -> TRUE | H3: =OFFSET('#Field'!$V$1, $E3+3, $D3) -> TRUE | I3: =OFFSET('#Field'!$V$1, $E3+1, $D3) -> 12
A4: 1 | B4: 3 | C4: 1,3 | D4: 1 | E4: 9 | F4: =OFFSET('#Field'!$V$1, $E4, $D4) -> chain_D_01 | G4: =OFFSET('#Field'!$V$1, $E4+2, $D4) -> TRUE | H4: =OFFSET('#Field'!$V$1, $E4+3, $D4) -> TRUE | I4: =OFFSET('#Field'!$V$1, $E4+1, $D4) -> 10
A5: 1 | B5: 4 | C5: 1,4 | D5: 1 | E5: 13 | F5: =OFFSET('#Field'!$V$1, $E5, $D5) -> chain_С_04 | G5: =OFFSET('#Field'!$V$1, $E5+2, $D5) -> TRUE | H5: =OFFSET('#Field'!$V$1, $E5+3, $D5) -> TRUE | I5: =OFFSET('#Field'!$V$1, $E5+1, $D5) -> 7
A6: 1 | B6: 5 | C6: 1,5 | D6: 1 | E6: 17 | F6: =OFFSET('#Field'!$V$1, $E6, $D6) -> chain_B_06 | G6: =OFFSET('#Field'!$V$1, $E6+2, $D6) -> TRUE | H6: =OFFSET('#Field'!$V$1, $E6+3, $D6) -> TRUE | I6: =OFFSET('#Field'!$V$1, $E6+1, $D6) -> 7
A7: 1 | B7: 6 | C7: 1,6 | D7: 1 | E7: 21 | F7: =OFFSET('#Field'!$V$1, $E7, $D7) -> chain_B_01 | G7: =OFFSET('#Field'!$V$1, $E7+2, $D7) -> TRUE | H7: =OFFSET('#Field'!$V$1, $E7+3, $D7) -> TRUE | I7: =OFFSET('#Field'!$V$1, $E7+1, $D7) -> 5
A8: 1 | B8: 7 | C8: 1,7 | D8: 1 | E8: 25 | F8: =OFFSET('#Field'!$V$1, $E8, $D8) -> chain_B_02 | G8: =OFFSET('#Field'!$V$1, $E8+2, $D8) -> TRUE | H8: =OFFSET('#Field'!$V$1, $E8+3, $D8) -> TRUE | I8: =OFFSET('#Field'!$V$1, $E8+1, $D8) -> 6
A9: 2 | B9: 1 | C9: 2,1 | D9: 5 | E9: 1 | F9: =OFFSET('#Field'!$V$1, $E9, $D9) -> chain_D_03 | G9: =OFFSET('#Field'!$V$1, $E9+2, $D9) -> TRUE | H9: =OFFSET('#Field'!$V$1, $E9+3, $D9) -> TRUE | I9: =OFFSET('#Field'!$V$1, $E9+1, $D9) -> 14
A10: 2 | B10: 2 | C10: 2,2 | D10: 5 | E10: 5 | F10: =OFFSET('#Field'!$V$1, $E10, $D10) -> chain_F_04 | G10: =OFFSET('#Field'!$V$1, $E10+2, $D10) -> TRUE | H10: =OFFSET('#Field'!$V$1, $E10+3, $D10) -> TRUE | I10: =OFFSET('#Field'!$V$1, $E10+1, $D10) -> 12
A11: 2 | B11: 3 | C11: 2,3 | D11: 5 | E11: 9 | F11: =OFFSET('#Field'!$V$1, $E11, $D11) -> chain_G_05 | G11: =OFFSET('#Field'!$V$1, $E11+2, $D11) -> TRUE | H11: =OFFSET('#Field'!$V$1, $E11+3, $D11) -> TRUE | I11: =OFFSET('#Field'!$V$1, $E11+1, $D11) -> 10
A12: 2 | B12: 4 | C12: 2,4 | D12: 5 | E12: 13 | F12: =OFFSET('#Field'!$V$1, $E12, $D12) -> chain_B_02 | G12: =OFFSET('#Field'!$V$1, $E12+2, $D12) -> TRUE | H12: =OFFSET('#Field'!$V$1, $E12+3, $D12) -> FALSE | I12: =OFFSET('#Field'!$V$1, $E12+1, $D12) -> 6
A13: 2 | B13: 5 | C13: 2,5 | D13: 5 | E13: 17 | F13: =OFFSET('#Field'!$V$1, $E13, $D13) -> chain_С_07 | G13: =OFFSET('#Field'!$V$1, $E13+2, $D13) -> TRUE | H13: =OFFSET('#Field'!$V$1, $E13+3, $D13) -> FALSE | I13: =OFFSET('#Field'!$V$1, $E13+1, $D13) -> 7
... A64: 9 | B64: 7 | C64: 9,7 | D64: 33 | E64: 25 | F64: =OFFSET('#Field'!$V$1, $E64, $D64) -> chain_B_01 | G64: =OFFSET('#Field'!$V$1, $E64+2, $D64) -> TRUE | H64: =OFFSET('#Field'!$V$1, $E64+3, $D64) -> TRUE | I64: =OFFSET('#Field'!$V$1, $E64+1, $D64) -> 6

Sheet Bubbles
A1: key | B1: value
A2: max_bubbles_on_board | B2: 5
A3: min_pass_lvl_for_bubbles_to_drop | B3: 5
A4: bubble_time_to_disappear | B4: 30

Sheet #Settings
A1: key | B1: value
A2: # Import
A3: # Test
A4: Prefix | B4: vampires_
A5: Base Index | B5: 1
A6: locked_visual | B6: vampires_locked_0
A7: closed_visual | B7: vampires_closed_0
A8: leveled_visual | B8: vampires_closed_by_lvl_0

Sheet #Data
A1: object_id | B1: text | C1: Image Path (Ref) | D1: Image (Ref) | E1: Chain | G1: # analog in TT
A2: generator_OR_01 | B2: Генератор обычных специй ур1 | E2: OR | G2: generator_OR_01
A3: generator_OR_02 | B3: Генератор обычных специй ур2 | E3: OR | G3: generator_OR_02
A4: generator_OR_03 | B4: Генератор обычных специй ур3 | E4: OR | G4: generator_OR_03
A5: generator_OR_04 | B5: Генератор обычных специй ур4 | E5: OR | G5: generator_OR_04
A6: generator_OR_05 | B6: Генератор обычных специй ур5 | E6: OR | G6: generator_OR_05
A7: generator_OR_06 | B7: Генератор обычных специй ур6 | E7: OR | G7: generator_OR_06
A8: =IF(ISBLANK(E8),, '#Settings'!$B$4 & E8 & "_0" & (COUNTIF($E$1:$E3, E8) + '#Settings'!$B$5))
A9: chain_A_01 | B9: роза ч1 | E9: A | G9: chain_A_01
A10: chain_A_02 | B10: роза ч2 | E10: A | G10: chain_A_02
A11: chain_A_03 | B11: роза | E11: A | G11: chain_A_03
A13: chain_B_01 | B13: анис ч1 | E13: B | G13: chain_B_01
A14: chain_B_02 | B14: анис ч2 | E14: B | G14: chain_B_02
A15: chain_B_03 | B15: анис ч3 | E15: B | G15: chain_B_03
A16: chain_B_04 | B16: анис | E16: B | G16: chain_B_04
A18: generator_RD_01 | B18: Генератор розовых специй ур1 | E18: RD | G18: generator_RD_01
A19: generator_RD_02 | B19: Генератор розовых специй ур2 | E19: RD | G19: generator_RD_02
A20: generator_RD_03 | B20: Генератор розовых специй ур3 | E20: RD | G20: generator_RD_03
A21: generator_RD_04 | B21: Генератор розовых специй ур4 | E21: RD | G21: generator_RD_04
A22: generator_RD_05 | B22: Генератор розовых специй ур5 | E22: RD | G22: generator_RD_05
... A43: generator_BL_06 | B43: генератор синих специй | E43: letter | G43: generator_BL_06
A44: =IF(ISBLANK(E44),, '#Settings'!$B$4 & E44 & "_0" & (COUNTIF($E$1:$E43, E44) + '#Settings'!$B$5))
A45: chain_E_01 | B45: женьшень 1 | E45: E | G45: chain_E_01
A46: chain_E_02 | B46: женьшень 2 | E46: E | G46: chain_E_02
A47: chain_E_03 | B47: женьшень 3 | E47: E | G47: chain_E_03
A48: chain_E_04 | B48: женьшень 4 | E48: E | G48: chain_E_04
A49: chain_E_05 | B49: женьшень 5 | E49: E | G49: chain_E_05
A50: chain_E_06 | B50: женьшень | E50: E | G50: chain_E_06
A52: chain_F_01 | B52: калган ч1 | E52: F | G52: chain_F_01
A53: chain_F_02 | B53: калган ч2 | E53: F | G53: chain_F_02
A54: chain_F_03 | B54: калган ч3 | E54: F | G54: chain_F_03
A55: chain_F_04 | B55: калган ч4 | E55: F | G55: chain_F_04
A56: chain_F_05 | B56: калган ч5 | E56: F | G56: chain_F_05
A57: chain_F_06 | B57: калган ч6 | E57: F | G57: chain_F_06
... A59: chain_F_08 | B59: калган | E59: F | G59: chain_F_08
A61: generator_GL_M_01 | B61: генератор золотых специй ур1 | G61: generator_GL_M_01
A62: generator_GL_M_02 | B62: генератор золотых специй ур2 | G62: generator_GL_M_02
A63: generator_GL_M_03 | B63: генератор золотых специй ур3 | G63: generator_GL_M_03
A64: generator_GL_M_04 | B64: генератор золотых специй ур4 | G64: generator_GL_M_04
A65: generator_GL_M_05 | B65: генератор золотых специй ур5 | G65: generator_GL_M_05
...

Sheet #Field
A1: y\x | B1: 1 | D1: 2 | F1: 3 | H1: 4 | J1: 5 | L1: 6 | N1: 7 | P1: 8 | R1: 9 | V1: y\x | W1: 1 | AA1: 2 | AE1: 3 | AI1: 4 | AM1: 5 | AQ1: 6 | AU1: 7 | AY1: 8 | BC1: 9 | BH1: {=DataIcons} -> Image (Ref) | BJ1: {=DataIDs} -> object_id
A2: 1 | B2: =IFS( $A$20, IFS( CONCATENATE(B39, B57, B75, "") = "", B21, ISBLANK(B75), B39 & B57, CONCATENATE(B39, B57, "") = "", B75, TRUE, B75 & CHAR(10) & B39 & B57 ), TRUE, B21 ) | D2: =IFS( $A$20, IFS( CONCATENATE(D39, D57, D75, "") = "", D21, ISBLANK(D75), D39 & D57, CONCATENATE(D39, D57, "") = "", D75, TRUE, D75 & CHAR(10) & D39 & D57 ), TRUE, D21 ) | F2: =IFS( $A$20, IFS( CONCATENATE(F39, F57, F75, "") = "", F21, ISBLANK(F75), F39 & F57, CONCATENATE(F39, F57, "") = "", F75, TRUE, F75 & CHAR(10) & F39 & F57 ), TRUE, F21 ) | H2: =IFS( $A$20, IFS( CONCATENATE(H39, H57, H75, "") = "", H21, ISBLANK(H75), H39 & H57, CONCATENATE(H39, H57, "") = "", H75, TRUE, H75 & CHAR(10) & H39 & H57 ), TRUE, H21 ) | J2: =IFS( $A$20, IFS( CONCATENATE(J39, J57, J75, "") = "", J21, ISBLANK(J75), J39 & J57, CONCATENATE(J39, J57, "") = "", J75, TRUE, J75 & CHAR(10) & J39 & J57 ), TRUE, J21 ) -> #N/A | L2: =IFS( $A$20, IFS( CONCATENATE(L39, L57, L75, "") = "", L21, ISBLANK(L75), L39 & L57, CONCATENATE(L39, L57, "") = "", L75, TRUE, L75 & CHAR(10) & L39 & L57 ), TRUE, L21 ) | N2: =IFS( $A$20, IFS( CONCATENATE(N39, N57, N75, "") = "", N21, ISBLANK(N75), N39 & N57, CONCATENATE(N39, N57, "") = "", N75, TRUE, N75 & CHAR(10) & N39 & N57 ), TRUE, N21 ) | P2: =IFS( $A$20, IFS( CONCATENATE(P39, P57, P75, "") = "", P21, ISBLANK(P75), P39 & P57, CONCATENATE(P39, P57, "") = "", P75, TRUE, P75 & CHAR(10) & P39 & P57 ), TRUE, P21 ) | R2: =IFS( $A$20, IFS( CONCATENATE(R39, R57, R75, "") = "", R21, ISBLANK(R75), R39 & R57, CONCATENATE(R39, R57, "") = "", R75, TRUE, R75 & CHAR(10) & R39 & R57 ), TRUE, R21 ) | V2: 1 | W2: chain_I_01 | Z2: {=IFS( ISBLANK(W2),, COUNTIF(DataIDs, W2) < 1, "❌", TRUE, VLOOKUP(W2, {DataIDs, DataIcons}, 2, FALSE) )} | AA2: chain_D_03 | AD2: {=IFS( ISBLANK(AA2),, COUNTIF(DataIDs, AA2) < 1, "❌", TRUE, VLOOKUP(AA2, {DataIDs, DataIcons}, 2, FALSE) )} | AE2: chain_I_02 | AH2: {=IFS( ISBLANK(AE2),, COUNTIF(DataIDs, AE2) < 1, "❌", TRUE, VLOOKUP(AE2, {DataIDs, DataIcons}, 2, FALSE) )} | AI2: chain_I_06 | AL2: {=IFS( ISBLANK(AI2),, COUNTIF(DataIDs, AI2) < 1, "❌", TRUE, VLOOKUP(AI2, {DataIDs, DataIcons}, 2, FALSE) )} | AM2: generator_GL_01 | AP2: {=IFS( ISBLANK(AM2),, COUNTIF(DataIDs, AM2) < 1, "❌", TRUE, VLOOKUP(AM2, {DataIDs, DataIcons}, 2, FALSE) )} -> ❌ | AQ2: chain_F_01 | AT2: {=IFS( ISBLANK(AQ2),, COUNTIF(DataIDs, AQ2) < 1, "❌", TRUE, VLOOKUP(AQ2, {DataIDs, DataIcons}, 2, FALSE) )} | AU2: chain_F_03 | AX2: {=IFS( ISBLANK(AU2),, COUNTIF(DataIDs, AU2) < 1, "❌", TRUE, VLOOKUP(AU2, {DataIDs, DataIcons}, 2, FALSE) )} | AY2: chain_D_03 | BB2: {=IFS( ISBLANK(AY2),, COUNTIF(DataIDs, AY2) < 1, "❌", TRUE, VLOOKUP(AY2, {DataIDs, DataIcons}, 2, FALSE) )} | BC2: chain_F_02 | BF2: {=IFS( ISBLANK(BC2),, COUNTIF(DataIDs, BC2) < 1, "❌", TRUE, VLOOKUP(BC2, {DataIDs, DataIcons}, 2, FALSE) )} | BJ2: generator_OR_01
W3: 14 | X3: =IF(W3, "⬅️",) -> ⬅️ | Y3: Level | AA3: 14 | AB3: =IF(AA3, "⬅️",) -> ⬅️ | AC3: Level | AE3: 12 | AF3: =IF(AE3, "⬅️",) -> ⬅️ | AG3: Level | AI3: 12 | AJ3: =IF(AI3, "⬅️",) -> ⬅️ | AK3: Level | AM3: 10 | AN3: =IF(AM3, "⬅️",) -> ⬅️ | AO3: Level | AQ3: 12 | AR3: =IF(AQ3, "⬅️",) -> ⬅️ | AS3: Level | AU3: 12 | AV3: =IF(AU3, "⬅️",) -> ⬅️ | AW3: Level | AY3: 14 | AZ3: =IF(AY3, "⬅️",) -> ⬅️ | BA3: Level | BC3: 14 | BD3: =IF(BC3, "⬅️",) -> ⬅️ | BE3: Level | BJ3: generator_OR_02 | BK3: =BH3
A4: 2 | B4: =IFS( $A$20, IFS( CONCATENATE(B41, B59, B77, "") = "", B23, ISBLANK(B77), B41 & B59, CONCATENATE(B41, B59, "") = "", B77, TRUE, B77 & CHAR(10) & B41 & B59 ), TRUE, B23 ) | D4: =IFS( $A$20, IFS( CONCATENATE(D41, D59, D77, "") = "", D23, ISBLANK(D77), D41 & D59, CONCATENATE(D41, D59, "") = "", D77, TRUE, D77 & CHAR(10) & D41 & D59 ), TRUE, D23 ) | F4: =IFS( $A$20, IFS( CONCATENATE(F41, F59, F77, "") = "", F23, ISBLANK(F77), F41 & F59, CONCATENATE(F41, F59, "") = "", F77, TRUE, F77 & CHAR(10) & F41 & F59 ), TRUE, F23 ) -> #N/A | H4: =IFS( $A$20, IFS( CONCATENATE(H41, H59, H77, "") = "", H23, ISBLANK(H77), H41 & H59, CONCATENATE(H41, H59, "") = "", H77, TRUE, H77 & CHAR(10) & H41 & H59 ), TRUE, H23 ) | J4: =IFS( $A$20, IFS( CONCATENATE(J41, J59, J77, "") = "", J23, ISBLANK(J77), J41 & J59, CONCATENATE(J41, J59, "") = "", J77, TRUE, J77 & CHAR(10) & J41 & J59 ), TRUE, J23 ) -> #N/A | L4: =IFS( $A$20, IFS( CONCATENATE(L41, L59, L77, "") = "", L23, ISBLANK(L77), L41 & L59, CONCATENATE(L41, L59, "") = "", L77, TRUE, L77 & CHAR(10) & L41 & L59 ), TRUE, L23 ) | N4: =IFS( $A$20, IFS( CONCATENATE(N41, N59, N77, "") = "", N23, ISBLANK(N77), N41 & N59, CONCATENATE(N41, N59, "") = "", N77, TRUE, N77 & CHAR(10) & N41 & N59 ), TRUE, N23 ) | P4: =IFS( $A$20, IFS( CONCATENATE(P41, P59, P77, "") = "", P23, ISBLANK(P77), P41 & P59, CONCATENATE(P41, P59, "") = "", P77, TRUE, P77 & CHAR(10) & P41 & P59 ), TRUE, P23 ) | R4: =IFS( $A$20, IFS( CONCATENATE(R41, R59, R77, "") = "", R23, ISBLANK(R77), R41 & R59, CONCATENATE(R41, R59, "") = "", R77, TRUE, R77 & CHAR(10) & R41 & R59 ), TRUE, R23 ) | W4: TRUE | X4: =IF(W4, "🔒",) -> 🔒 | Y4: Locked | AA4: TRUE | AB4: =IF(AA4, "🔒",) -> 🔒 | AC4: Locked | AE4: TRUE | AF4: =IF(AE4, "🔒",) -> 🔒 | AG4: Locked | AI4: TRUE | AJ4: =IF(AI4, "🔒",) -> 🔒 | AK4: Locked | AM4: FALSE | AN4: =IF(AM4, "🔒",) | AO4: Locked | AQ4: TRUE | AR4: =IF(AQ4, "🔒",) -> 🔒 | AS4: Locked | AU4: TRUE | AV4: =IF(AU4, "🔒",) -> 🔒 | AW4: Locked | AY4: TRUE | AZ4: =IF(AY4, "🔒",) -> 🔒 | BA4: Locked | BC4: TRUE | BD4: =IF(BC4, "🔒",) -> 🔒 | BE4: Locked | BJ4: generator_OR_03
W5: TRUE | X5: =IF(W5, "💀",) -> 💀 | Y5: Closed | AA5: TRUE | AB5: =IF(AA5, "💀",) -> 💀 | AC5: Closed | AE5: TRUE | AF5: =IF(AE5, "💀",) -> 💀 | AG5: Closed | AI5: TRUE | AJ5: =IF(AI5, "💀",) -> 💀 | AK5: Closed | AM5: FALSE | AN5: =IF(AM5, "💀",) | AO5: Closed | AQ5: TRUE | AR5: =IF(AQ5, "💀",) -> 💀 | AS5: Closed | AU5: FALSE | AV5: =IF(AU5, "💀",) | AW5: Closed | AY5: TRUE | AZ5: =IF(AY5, "💀",) -> 💀 | BA5: Closed | BC5: TRUE | BD5: =IF(BC5, "💀",) -> 💀 | BE5: Closed | BJ5: generator_OR_04 | BK5: =BH5
A6: 3 | B6: =IFS( $A$20, IFS( CONCATENATE(B43, B61, B79, "") = "", B25, ISBLANK(B79), B43 & B61, CONCATENATE(B43, B61, "") = "", B79, TRUE, B79 & CHAR(10) & B43 & B61 ), TRUE, B25 ) | D6: =IFS( $A$20, IFS( CONCATENATE(D43, D61, D79, "") = "", D25, ISBLANK(D79), D43 & D61, CONCATENATE(D43, D61, "") = "", D79, TRUE, D79 & CHAR(10) & D43 & D61 ), TRUE, D25 ) | F6: =IFS( $A$20, IFS( CONCATENATE(F43, F61, F79, "") = "", F25, ISBLANK(F79), F43 & F61, CONCATENATE(F43, F61, "") = "", F79, TRUE, F79 & CHAR(10) & F43 & F61 ), TRUE, F25 ) -> #N/A | H6: =IFS( $A$20, IFS( CONCATENATE(H43, H61, H79, "") = "", H25, ISBLANK(H79), H43 & H61, CONCATENATE(H43, H61, "") = "", H79, TRUE, H79 & CHAR(10) & H43 & H61 ), TRUE, H25 ) -> #N/A | J6: =IFS( $A$20, IFS( CONCATENATE(J43, J61, J79, "") = "", J25, ISBLANK(J79), J43 & J61, CONCATENATE(J43, J61, "") = "", J79, TRUE, J79 & CHAR(10) & J43 & J61 ), TRUE, J25 ) -> #N/A | L6: =IFS( $A$20, IFS( CONCATENATE(L43, L61, L79, "") = "", L25, ISBLANK(L79), L43 & L61, CONCATENATE(L43, L61, "") = "", L79, TRUE, L79 & CHAR(10) & L43 & L61 ), TRUE, L25 ) -> #N/A | N6: =IFS( $A$20, IFS( CONCATENATE(N43, N61, N79, "") = "", N25, ISBLANK(N79), N43 & N61, CONCATENATE(N43, N61, "") = "", N79, TRUE, N79 & CHAR(10) & N43 & N61 ), TRUE, N25 ) -> #N/A | P6: =IFS( $A$20, IFS( CONCATENATE(P43, P61, P79, "") = "", P25, ISBLANK(P79), P43 & P61, CONCATENATE(P43, P61, "") = "", P79, TRUE, P79 & CHAR(10) & P43 & P61 ), TRUE, P25 ) | R6: =IFS( $A$20, IFS( CONCATENATE(R43, R61, R79, "") = "", R25, ISBLANK(R79), R43 & R61, CONCATENATE(R43, R61, "") = "", R79, TRUE, R79 & CHAR(10) & R43 & R61 ), TRUE, R25 ) | V6: 2 | W6: chain_D_02 | Z6: {=IFS( ISBLANK(W6),, COUNTIF(DataIDs, W6) < 1, "❌", TRUE, VLOOKUP(W6, {DataIDs, DataIcons}, 2, FALSE) )} | AA6: chain_F_04 | AD6: {=IFS( ISBLANK(AA6),, COUNTIF(DataIDs, AA6) < 1, "❌", TRUE, VLOOKUP(AA6, {DataIDs, DataIcons}, 2, FALSE) )} | AE6: chain_С_03 | AH6: {=IFS( ISBLANK(AE6),, COUNTIF(DataIDs, AE6) < 1, "❌", TRUE, VLOOKUP(AE6, {DataIDs, DataIcons}, 2, FALSE) )} -> ❌ | AI6: chain_I_03 | AL6: {=IFS( ISBLANK(AI6),, COUNTIF(DataIDs, AI6) < 1, "❌", TRUE, VLOOKUP(AI6, {DataIDs, DataIcons}, 2, FALSE) )} | AM6: chain_С_05 | AP6: {=IFS( ISBLANK(AM6),, COUNTIF(DataIDs, AM6) < 1, "❌", TRUE, VLOOKUP(AM6, {DataIDs, DataIcons}, 2, FALSE) )} -> ❌ | AQ6: chain_D_01 | AT6: {=IFS( ISBLANK(AQ6),, COUNTIF(DataIDs, AQ6) < 1, "❌", TRUE, VLOOKUP(AQ6, {DataIDs, DataIcons}, 2, FALSE) )} | AU6: chain_G_01 | AX6: {=IFS( ISBLANK(AU6),, COUNTIF(DataIDs, AU6) < 1, "❌", TRUE, VLOOKUP(AU6, {DataIDs, DataIcons}, 2, FALSE) )} | AY6: chain_G_03 | BB6: {=IFS( ISBLANK(AY6),, COUNTIF(DataIDs, AY6) < 1, "❌", TRUE, VLOOKUP(AY6, {DataIDs, DataIcons}, 2, FALSE) )} | BC6: chain_F_06 | BF6: {=IFS( ISBLANK(BC6),, COUNTIF(DataIDs, BC6) < 1, "❌", TRUE, VLOOKUP(BC6, {DataIDs, DataIcons}, 2, FALSE) )} | BJ6: generator_OR_05
W7: 12 | X7: =IF(W7, "⬅️",) -> ⬅️ | Y7: Level | AA7: 12 | AB7: =IF(AA7, "⬅️",) -> ⬅️ | AC7: Level | AE7: 10 | AF7: =IF(AE7, "⬅️",) -> ⬅️ | AG7: Level | AI7: 10 | AJ7: =IF(AI7, "⬅️",) -> ⬅️ | AK7: Level | AM7: 10 | AN7: =IF(AM7, "⬅️",) -> ⬅️ | AO7: Level | AQ7: 10 | AR7: =IF(AQ7, "⬅️",) -> ⬅️ | AS7: Level | AU7: 10 | AV7: =IF(AU7, "⬅️",) -> ⬅️ | AW7: Level | AY7: 12 | AZ7: =IF(AY7, "⬅️",) -> ⬅️ | BA7: Level | BC7: 12 | BD7: =IF(BC7, "⬅️",) -> ⬅️ | BE7: Level | BJ7: generator_OR_06 | BK7: =BH7
A8: 4 | B8: =IFS( $A$20, IFS( CONCATENATE(B45, B63, B81, "") = "", B27, ISBLANK(B81), B45 & B63, CONCATENATE(B45, B63, "") = "", B81, TRUE, B81 & CHAR(10) & B45 & B63 ), TRUE, B27 ) -> #N/A | D8: =IFS( $A$20, IFS( CONCATENATE(D45, D63, D81, "") = "", D27, ISBLANK(D81), D45 & D63, CONCATENATE(D45, D63, "") = "", D81, TRUE, D81 & CHAR(10) & D45 & D63 ), TRUE, D27 ) | F8: =IFS( $A$20, IFS( CONCATENATE(F45, F63, F81, "") = "", F27, ISBLANK(F81), F45 & F63, CONCATENATE(F45, F63, "") = "", F81, TRUE, F81 & CHAR(10) & F45 & F63 ), TRUE, F27 ) | H8: =IFS( $A$20, IFS( CONCATENATE(H45, H63, H81, "") = "", H27, ISBLANK(H81), H45 & H63, CONCATENATE(H45, H63, "") = "", H81, TRUE, H81 & CHAR(10) & H45 & H63 ), TRUE, H27 ) -> #N/A | J8: =IFS( $A$20, IFS( CONCATENATE(J45, J63, J81, "") = "", J27, ISBLANK(J81), J45 & J63, CONCATENATE(J45, J63, "") = "", J81, TRUE, J81 & CHAR(10) & J45 & J63 ), TRUE, J27 ) | L8: =IFS( $A$20, IFS( CONCATENATE(L45, L63, L81, "") = "", L27, ISBLANK(L81), L45 & L63, CONCATENATE(L45, L63, "") = "", L81, TRUE, L81 & CHAR(10) & L45 & L63 ), TRUE, L27 ) | N8: =IFS( $A$20, IFS( CONCATENATE(N45, N63, N81, "") = "", N27, ISBLANK(N81), N45 & N63, CONCATENATE(N45, N63, "") = "", N81, TRUE, N81 & CHAR(10) & N45 & N63 ), TRUE, N27 ) -> #N/A | P8: =IFS( $A$20, IFS( CONCATENATE(P45, P63, P81, "") = "", P27, ISBLANK(P81), P45 & P63, CONCATENATE(P45, P63, "") = "", P81, TRUE, P81 & CHAR(10) & P45 & P63 ), TRUE, P27 ) -> #N/A | R8: =IFS( $A$20, IFS( CONCATENATE(R45, R63, R81, "") = "", R27, ISBLANK(R81), R45 & R63, CONCATENATE(R45, R63, "") = "", R81, TRUE, R81 & CHAR(10) & R45 & R63 ), TRUE, R27 ) -> #N/A | W8: TRUE | X8: =IF(W8, "🔒",) -> 🔒 | Y8: Locked | AA8: TRUE | AB8: =IF(AA8, "🔒",) -> 🔒 | AC8: Locked | AE8: TRUE | AF8: =IF(AE8, "🔒",) -> 🔒 | AG8: Locked | AI8: TRUE | AJ8: =IF(AI8, "🔒",) -> 🔒 | AK8: Locked | AM8: TRUE | AN8: =IF(AM8, "🔒",) -> 🔒 | AO8: Locked | AQ8: TRUE | AR8: =IF(AQ8, "🔒",) -> 🔒 | AS8: Locked | AU8: TRUE | AV8: =IF(AU8, "🔒",) -> 🔒 | AW8: Locked | AY8: TRUE | AZ8: =IF(AY8, "🔒",) -> 🔒 | BA8: Locked | BC8: TRUE | BD8: =IF(BC8, "🔒",) -> 🔒 | BE8: Locked
W9: TRUE | X9: =IF(W9, "💀",) -> 💀 | Y9: Closed | AA9: TRUE | AB9: =IF(AA9, "💀",) -> 💀 | AC9: Closed | AE9: TRUE | AF9: =IF(AE9, "💀",) -> 💀 | AG9: Closed | AI9: FALSE | AJ9: =IF(AI9, "💀",) | AK9: Closed | AM9: FALSE | AN9: =IF(AM9, "💀",) | AO9: Closed | AQ9: FALSE | AR9: =IF(AQ9, "💀",) | AS9: Closed | AU9: TRUE | AV9: =IF(AU9, "💀",) -> 💀 | AW9: Closed | AY9: TRUE | AZ9: =IF(AY9, "💀",) -> 💀 | BA9: Closed | BC9: TRUE | BD9: =IF(BC9, "💀",) -> 💀 | BE9: Closed | BJ9: chain_A_01 | BK9: =BH9
A10: 5 | B10: =IFS( $A$20, IFS( CONCATENATE(B47, B65, B83, "") = "", B29, ISBLANK(B83), B47 & B65, CONCATENATE(B47, B65, "") = "", B83, TRUE, B83 & CHAR(10) & B47 & B65 ), TRUE, B29 ) -> #N/A | D10: =IFS( $A$20, IFS( CONCATENATE(D47, D65, D83, "") = "", D29, ISBLANK(D83), D47 & D65, CONCATENATE(D47, D65, "") = "", D83, TRUE, D83 & CHAR(10) & D47 & D65 ), TRUE, D29 ) -> #N/A | F10: =IFS( $A$20, IFS( CONCATENATE(F47, F65, F83, "") = "", F29, ISBLANK(F83), F47 & F65, CONCATENATE(F47, F65, "") = "", F83, TRUE, F83 & CHAR(10) & F47 & F65 ), TRUE, F29 ) | H10: =IFS( $A$20, IFS( CONCATENATE(H47, H65, H83, "") = "", H29, ISBLANK(H83), H47 & H65, CONCATENATE(H47, H65, "") = "", H83, TRUE, H83 & CHAR(10) & H47 & H65 ), TRUE, H29 ) | J10: =IFS( $A$20, IFS( CONCATENATE(J47, J65, J83, "") = "", J29, ISBLANK(J83), J47 & J65, CONCATENATE(J47, J65, "") = "", J83, TRUE, J83 & CHAR(10) & J47 & J65 ), TRUE, J29 ) | L10: =IFS( $A$20, IFS( CONCATENATE(L47, L65, L83, "") = "", L29, ISBLANK(L83), L47 & L65, CONCATENATE(L47, L65, "") = "", L83, TRUE, L83 & CHAR(10) & L47 & L65 ), TRUE, L29 ) -> #N/A | N10: =IFS( $A$20, IFS( CONCATENATE(N47, N65, N83, "") = "", N29, ISBLANK(N83), N47 & N65, CONCATENATE(N47, N65, "") = "", N83, TRUE, N83 & CHAR(10) & N47 & N65 ), TRUE, N29 ) | P10: =IFS( $A$20, IFS( CONCATENATE(P47, P65, P83, "") = "", P29, ISBLANK(P83), P47 & P65, CONCATENATE(P47, P65, "") = "", P83, TRUE, P83 & CHAR(10) & P47 & P65 ), TRUE, P29 ) -> #N/A | R10: =IFS( $A$20, IFS( CONCATENATE(R47, R65, R83, "") = "", R29, ISBLANK(R83), R47 & R65, CONCATENATE(R47, R65, "") = "", R83, TRUE, R83 & CHAR(10) & R47 & R65 ), TRUE, R29 ) -> #N/A | V10: 3 | W10: chain_D_01 | Z10: {=IFS( ISBLANK(W10),, COUNTIF(DataIDs, W10) < 1, "❌", TRUE, VLOOKUP(W10, {DataIDs, DataIcons}, 2, FALSE) )} | AA10: chain_G_05 | AD10: {=IFS( ISBLANK(AA10),, COUNTIF(DataIDs, AA10) < 1, "❌", TRUE, VLOOKUP(AA10, {DataIDs, DataIcons}, 2, FALSE) )} | AE10: chain_С_03 | AH10: {=IFS( ISBLANK(AE10),, COUNTIF(DataIDs, AE10) < 1, "❌", TRUE, VLOOKUP(AE10, {DataIDs, DataIcons}, 2, FALSE) )} -> ❌ | AI10: chain_B_06 | AL10: {=IFS( ISBLANK(AI10),, COUNTIF(DataIDs, AI10) < 1, "❌", TRUE, VLOOKUP(AI10, {DataIDs, DataIcons}, 2, FALSE) )} -> ❌ | AM10: chain_С_04 | AP10: {=IFS( ISBLANK(AM10),, COUNTIF(DataIDs, AM10) < 1, "❌", TRUE, VLOOKUP(AM10, {DataIDs, DataIcons}, 2, FALSE) )} -> ❌ | AQ10: chain_С_08 | AT10: {=IFS( ISBLANK(AQ10),, COUNTIF(DataIDs, AQ10) < 1, "❌", TRUE, VLOOKUP(AQ10, {DataIDs, DataIcons}, 2, FALSE) )} -> ❌ | AU10: chain_С_02 | AX10: {=IFS( ISBLANK(AU10),, COUNTIF(DataIDs, AU10) < 1, "❌", TRUE, VLOOKUP(AU10, {DataIDs, DataIcons}, 2, FALSE) )} -> ❌ | AY10: chain_D_02 | BB10: {=IFS( ISBLANK(AY10),, COUNTIF(DataIDs, AY10) < 1, "❌", TRUE, VLOOKUP(AY10, {DataIDs, DataIcons}, 2, FALSE) )} | BC10: chain_I_04 | BF10: {=IFS( ISBLANK(BC10),, COUNTIF(DataIDs, BC10) < 1, "❌", TRUE, VLOOKUP(BC10, {DataIDs, DataIcons}, 2, FALSE) )} | BJ10: chain_A_02
W11: 10 | X11: =IF(W11, "⬅️",) -> ⬅️ | Y11: Level | AA11: 10 | AB11: =IF(AA11, "⬅️",) -> ⬅️ | AC11: Level | AE11: 8 | AF11: =IF(AE11, "⬅️",) -> ⬅️ | AG11: Level | AI11: 8 | AJ11: =IF(AI11, "⬅️",) -> ⬅️ | AK11: Level | AM11: 8 | AN11: =IF(AM11, "⬅️",) -> ⬅️ | AO11: Level | AQ11: 8 | AR11: =IF(AQ11, "⬅️",) -> ⬅️ | AS11: Level | AU11: 8 | AV11: =IF(AU11, "⬅️",) -> ⬅️ | AW11: Level | AY11: 10 | AZ11: =IF(AY11, "⬅️",) -> ⬅️ | BA11: Level | BC11: 10 | BD11: =IF(BC11, "⬅️",) -> ⬅️ | BE11: Level | BJ11: chain_A_03 | BK11: =BH11
A12: 6 | B12: =IFS( $A$20, IFS( CONCATENATE(B49, B67, B85, "") = "", B31, ISBLANK(B85), B49 & B67, CONCATENATE(B49, B67, "") = "", B85, TRUE, B85 & CHAR(10) & B49 & B67 ), TRUE, B31 ) | D12: =IFS( $A$20, IFS( CONCATENATE(D49, D67, D85, "") = "", D31, ISBLANK(D85), D49 & D67, CONCATENATE(D49, D67, "") = "", D85, TRUE, D85 & CHAR(10) & D49 & D67 ), TRUE, D31 ) | F12: =IFS( $A$20, IFS( CONCATENATE(F49, F67, F85, "") = "", F31, ISBLANK(F85), F49 & F67, CONCATENATE(F49, F67, "") = "", F85, TRUE, F85 & CHAR(10) & F49 & F67 ), TRUE, F31 ) | H12: =IFS( $A$20, IFS( CONCATENATE(H49, H67, H85, "") = "", H31, ISBLANK(H85), H49 & H67, CONCATENATE(H49, H67, "") = "", H85, TRUE, H85 & CHAR(10) & H49 & H67 ), TRUE, H31 ) | J12: =IFS( $A$20, IFS( CONCATENATE(J49, J67, J85, "") = "", J31, ISBLANK(J85), J49 & J67, CONCATENATE(J49, J67, "") = "", J85, TRUE, J85 & CHAR(10) & J49 & J67 ), TRUE, J31 ) | L12: =IFS( $A$20, IFS( CONCATENATE(L49, L67, L85, "") = "", L31, ISBLANK(L85), L49 & L67, CONCATENATE(L49, L67, "") = "", L85, TRUE, L85 & CHAR(10) & L49 & L67 ), TRUE, L31 ) | N12: =IFS( $A$20, IFS( CONCATENATE(N49, N67, N85, "") = "", N31, ISBLANK(N85), N49 & N67, CONCATENATE(N49, N67, "") = "", N85, TRUE, N85 & CHAR(10) & N49 & N67 ), TRUE, N31 ) | P12: =IFS( $A$20, IFS( CONCATENATE(P49, P67, P85, "") = "", P31, ISBLANK(P85), P49 & P67, CONCATENATE(P49, P67, "") = "", P85, TRUE, P85 & CHAR(10) & P49 & P67 ), TRUE, P31 ) | R12: =IFS( $A$20, IFS( CONCATENATE(R49, R67, R85, "") = "", R31, ISBLANK(R85), R49 & R67, CONCATENATE(R49, R67, "") = "", R85, TRUE, R85 & CHAR(10) & R49 & R67 ), TRUE, R31 ) | W12: TRUE | X12: =IF(W12, "🔒",) -> 🔒 | Y12: Locked | AA12: TRUE | AB12: =IF(AA12, "🔒",) -> 🔒 | AC12: Locked | AE12: TRUE | AF12: =IF(AE12, "🔒",) -> 🔒 | AG12: Locked | AI12: TRUE | AJ12: =IF(AI12, "🔒",) -> 🔒 | AK12: Locked | AM12: TRUE | AN12: =IF(AM12, "🔒",) -> 🔒 | AO12: Locked | AQ12: TRUE | AR12: =IF(AQ12, "🔒",) -> 🔒 | AS12: Locked | AU12: TRUE | AV12: =IF(AU12, "🔒",) -> 🔒 | AW12: Locked | AY12: TRUE | AZ12: =IF(AY12, "🔒",) -> 🔒 | BA12: Locked | BC12: TRUE | BD12: =IF(BC12, "🔒",) -> 🔒 | BE12: Locked
W13: TRUE | X13: =IF(W13, "💀",) -> 💀 | Y13: Closed | AA13: TRUE | AB13: =IF(AA13, "💀",) -> 💀 | AC13: Closed | AE13: FALSE | AF13: =IF(AE13, "💀",) | AG13: Closed | AI13: FALSE | AJ13: =IF(AI13, "💀",) | AK13: Closed | AM13: FALSE | AN13: =IF(AM13, "💀",) | AO13: Closed | AQ13: FALSE | AR13: =IF(AQ13, "💀",) | AS13: Closed | AU13: FALSE | AV13: =IF(AU13, "💀",) | AW13: Closed | AY13: TRUE | AZ13: =IF(AY13, "💀",) -> 💀 | BA13: Closed | BC13: TRUE | BD13: =IF(BC13, "💀",) -> 💀 | BE13: Closed | BJ13: chain_B_01 | BK13: =BH13
A14: 7 | B14: =IFS( $A$20, IFS( CONCATENATE(B51, B69, B87, "") = "", B33, ISBLANK(B87), B51 & B69, CONCATENATE(B51, B69, "") = "", B87, TRUE, B87 & CHAR(10) & B51 & B69 ), TRUE, B33 ) | D14: =IFS( $A$20, IFS( CONCATENATE(D51, D69, D87, "") = "", D33, ISBLANK(D87), D51 & D69, CONCATENATE(D51, D69, "") = "", D87, TRUE, D87 & CHAR(10) & D51 & D69 ), TRUE, D33 ) -> #N/A | F14: =IFS( $A$20, IFS( CONCATENATE(F51, F69, F87, "") = "", F33, ISBLANK(F87), F51 & F69, CONCATENATE(F51, F69, "") = "", F87, TRUE, F87 & CHAR(10) & F51 & F69 ), TRUE, F33 ) | H14: =IFS( $A$20, IFS( CONCATENATE(H51, H69, H87, "") = "", H33, ISBLANK(H87), H51 & H69, CONCATENATE(H51, H69, "") = "", H87, TRUE, H87 & CHAR(10) & H51 & H69 ), TRUE, H33 ) | J14: =IFS( $A$20, IFS( CONCATENATE(J51, J69, J87, "") = "", J33, ISBLANK(J87), J51 & J69, CONCATENATE(J51, J69, "") = "", J87, TRUE, J87 & CHAR(10) & J51 & J69 ), TRUE, J33 ) | L14: =IFS( $A$20, IFS( CONCATENATE(L51, L69, L87, "") = "", L33, ISBLANK(L87), L51 & L69, CONCATENATE(L51, L69, "") = "", L87, TRUE, L87 & CHAR(10) & L51 & L69 ), TRUE, L33 ) | N14: =IFS( $A$20, IFS( CONCATENATE(N51, N69, N87, "") = "", N33, ISBLANK(N87), N51 & N69, CONCATENATE(N51, N69, "") = "", N87, TRUE, N87 & CHAR(10) & N51 & N69 ), TRUE, N33 ) -> #N/A | P14: =IFS( $A$20, IFS( CONCATENATE(P51, P69, P87, "") = "", P33, ISBLANK(P87), P51 & P69, CONCATENATE(P51, P69, "") = "", P87, TRUE, P87 & CHAR(10) & P51 & P69 ), TRUE, P33 ) | R14: =IFS( $A$20, IFS( CONCATENATE(R51, R69, R87, "") = "", R33, ISBLANK(R87), R51 & R69, CONCATENATE(R51, R69, "") = "", R87, TRUE, R87 & CHAR(10) & R51 & R69 ), TRUE, R33 ) | V14: 4 | W14: chain_С_04 | Z14: {=IFS( ISBLANK(W14),, COUNTIF(DataIDs, W14) < 1, "❌", TRUE, VLOOKUP(W14, {DataIDs, DataIcons}, 2, FALSE) )} -> ❌ | AA14: chain_B_02 | AD14: {=IFS( ISBLANK(AA14),, COUNTIF(DataIDs, AA14) < 1, "❌", TRUE, VLOOKUP(AA14, {DataIDs, DataIcons}, 2, FALSE) )} | AE14: chain_B_04 | AH14: {=IFS( ISBLANK(AE14),, COUNTIF(DataIDs, AE14) < 1, "❌", TRUE, VLOOKUP(AE14, {DataIDs, DataIcons}, 2, FALSE) )} | AI14: chain_С_02 | AL14: {=IFS( ISBLANK(AI14),, COUNTIF(DataIDs, AI14) < 1, "❌", TRUE, VLOOKUP(AI14, {DataIDs, DataIcons}, 2, FALSE) )} -> ❌ | AM14: generator_BL_01 | AP14: {=IFS( ISBLANK(AM14),, COUNTIF(DataIDs, AM14) < 1, "❌", TRUE, VLOOKUP(AM14, {DataIDs, DataIcons}, 2, FALSE) )} | AQ14: chain_B_03 | AT14: {=IFS( ISBLANK(AQ14),, COUNTIF(DataIDs, AQ14) < 1, "❌", TRUE, VLOOKUP(AQ14, {DataIDs, DataIcons}, 2, FALSE) )} | AU14: chain_С_01 | AX14: {=IFS( ISBLANK(AU14),, COUNTIF(DataIDs, AU14) < 1, "❌", TRUE, VLOOKUP(AU14, {DataIDs, DataIcons}, 2, FALSE) )} -> ❌ | AY14: chain_С_06 | BB14: {=IFS( ISBLANK(AY14),, COUNTIF(DataIDs, AY14) < 1, "❌", TRUE, VLOOKUP(AY14, {DataIDs, DataIcons}, 2, FALSE) )} -> ❌ | BC14: chain_B_05 | BF14: {=IFS( ISBLANK(BC14),, COUNTIF(DataIDs, BC14) < 1, "❌", TRUE, VLOOKUP(BC14, {DataIDs, DataIcons}, 2, FALSE) )} -> ❌ | BJ14: chain_B_02
W15: 7 | X15: =IF(W15, "⬅️",) -> ⬅️ | Y15: Level | AA15: 6 | AB15: =IF(AA15, "⬅️",) -> ⬅️ | AC15: Level | AE15: 7 | AF15: =IF(AE15, "⬅️",) -> ⬅️ | AG15: Level | AI15: 7 | AJ15: =IF(AI15, "⬅️",) -> ⬅️ | AK15: Level | AM15: 7 | AN15: =IF(AM15, "⬅️",) -> ⬅️ | AO15: Level | AQ15: 7 | AR15: =IF(AQ15, "⬅️",) -> ⬅️ | AS15: Level | AU15: 7 | AV15: =IF(AU15, "⬅️",) -> ⬅️ | AW15: Level | AY15: 7 | AZ15: =IF(AY15, "⬅️",) -> ⬅️ | BA15: Level | BC15: 7 | BD15: =IF(BC15, "⬅️",) -> ⬅️ | BE15: Level | BJ15: chain_B_03 | BK15: =BH15
A16: 8 | B16: ⬆️ THIS IS MY CAFE MERGE FIELD ⬆️ | W16: TRUE | X16: =IF(W16, "🔒",) -> 🔒 | Y16: Locked | AA16: TRUE | AB16: =IF(AA16, "🔒",) -> 🔒 | AC16: Locked | AE16: TRUE | AF16: =IF(AE16, "🔒",) -> 🔒 | AG16: Locked | AI16: TRUE | AJ16: =IF(AI16, "🔒",) -> 🔒 | AK16: Locked | AM16: TRUE | AN16: =IF(AM16, "🔒",) -> 🔒 | AO16: Locked | AQ16: TRUE | AR16: =IF(AQ16, "🔒",) -> 🔒 | AS16: Locked | AU16: TRUE | AV16: =IF(AU16, "🔒",) -> 🔒 | AW16: Locked | AY16: TRUE | AZ16: =IF(AY16, "🔒",) -> 🔒 | BA16: Locked | BC16: TRUE | BD16: =IF(BC16, "🔒",) -> 🔒 | BE16: Locked | BJ16: chain_B_04
W17: TRUE | X17: =IF(W17, "💀",) -> 💀 | Y17: Closed | AA17: FALSE | AB17: =IF(AA17, "💀",) | AC17: Closed | AE17: TRUE | AF17: =IF(AE17, "💀",) -> 💀 | AG17: Closed | AI17: TRUE | AJ17: =IF(AI17, "💀",) -> 💀 | AK17: Closed | AM17: FALSE | AN17: =IF(AM17, "💀",) | AO17: Closed | AQ17: TRUE | AR17: =IF(AQ17, "💀",) -> 💀 | AS17: Closed | AU17: FALSE | AV17: =IF(AU17, "💀",) | AW17: Closed | AY17: FALSE | AZ17: =IF(AY17, "💀",) | BA17: Closed | BC17: TRUE | BD17: =IF(BC17, "💀",) -> 💀 | BE17: Closed | BK17: =BH17
A18: 9 | V18: 5 | W18: chain_B_06 | Z18: {=IFS( ISBLANK(W18),, COUNTIF(DataIDs, W18) < 1, "❌", TRUE, VLOOKUP(W18, {DataIDs, DataIcons}, 2, FALSE) )} -> ❌ | AA18: chain_С_07 | AD18: {=IFS( ISBLANK(AA18),, COUNTIF(DataIDs, AA18) < 1, "❌", TRUE, VLOOKUP(AA18, {DataIDs, DataIcons}, 2, FALSE) )} -> ❌ | AE18: chain_B_02 | AH18: {=IFS( ISBLANK(AE18),, COUNTIF(DataIDs, AE18) < 1, "❌", TRUE, VLOOKUP(AE18, {DataIDs, DataIcons}, 2, FALSE) )} | AI18: =$BJ$13 -> chain_B_01 | AL18: {=IFS( ISBLANK(AI18),, COUNTIF(DataIDs, AI18) < 1, "❌", TRUE, VLOOKUP(AI18, {DataIDs, DataIcons}, 2, FALSE) )} | AM18: chain_A_03 | AP18: {=IFS( ISBLANK(AM18),, COUNTIF(DataIDs, AM18) < 1, "❌", TRUE, VLOOKUP(AM18, {DataIDs, DataIcons}, 2, FALSE) )} | AQ18: chain_A_04 | AT18: {=IFS( ISBLANK(AQ18),, COUNTIF(DataIDs, AQ18) < 1, "❌", TRUE, VLOOKUP(AQ18, {DataIDs, DataIcons}, 2, FALSE) )} -> ❌ | AU18: chain_A_02 | AX18: {=IFS( ISBLANK(AU18),, COUNTIF(DataIDs, AU18) < 1, "❌", TRUE, VLOOKUP(AU18, {DataIDs, DataIcons}, 2, FALSE) )} | AY18: chain_С_03 | BB18: {=IFS( ISBLANK(AY18),, COUNTIF(DataIDs, AY18) < 1, "❌", TRUE, VLOOKUP(AY18, {DataIDs, DataIcons}, 2, FALSE) )} -> ❌ | BC18: chain_С_04 | BF18: {=IFS( ISBLANK(BC18),, COUNTIF(DataIDs, BC18) < 1, "❌", TRUE, VLOOKUP(BC18, {DataIDs, DataIcons}, 2, FALSE) )} -> ❌ | BJ18: generator_RD_01
W19: 7 | X19: =IF(W19, "⬅️",) -> ⬅️ | Y19: Level | AA19: 7 | AB19: =IF(AA19, "⬅️",) -> ⬅️ | AC19: Level | AE19: 6 | AF19: =IF(AE19, "⬅️",) -> ⬅️ | AG19: Level | AI19: 5 | AJ19: =IF(AI19, "⬅️",) -> ⬅️ | AK19: Level | AM19: 5 | AN19: =IF(AM19, "⬅️",) -> ⬅️ | AO19: Level | AQ19: 5 | AR19: =IF(AQ19, "⬅️",) -> ⬅️ | AS19: Level | AU19: 5 | AV19: =IF(AU19, "⬅️",) -> ⬅️ | AW19: Level | AY19: 7 | AZ19: =IF(AY19, "⬅️",) -> ⬅️ | BA19: Level | BC19: 7 | BD19: =IF(BC19, "⬅️",) -> ⬅️ | BE19: Level | BJ19: generator_RD_02 | BK19: =BH19
A20: FALSE | B20: Show: Locked / Closed / Level | W20: TRUE | X20: =IF(W20, "🔒",) -> 🔒 | Y20: Locked | AA20: TRUE | AB20: =IF(AA20, "🔒",) -> 🔒 | AC20: Locked | AE20: TRUE | AF20: =IF(AE20, "🔒",) -> 🔒 | AG20: Locked | AI20: TRUE | AJ20: =IF(AI20, "🔒",) -> 🔒 | AK20: Locked | AM20: TRUE | AN20: =IF(AM20, "🔒",) -> 🔒 | AO20: Locked | AQ20: TRUE | AR20: =IF(AQ20, "🔒",) -> 🔒 | AS20: Locked | AU20: TRUE | AV20: =IF(AU20, "🔒",) -> 🔒 | AW20: Locked | AY20: TRUE | AZ20: =IF(AY20, "🔒",) -> 🔒 | BA20: Locked | BC20: TRUE | BD20: =IF(BC20, "🔒",) -> 🔒 | BE20: Locked | BJ20: generator_RD_03
A21: Images | B21: {=IFS( COUNTIF(Field!$C$2:$C593, B$1 & "," & $A2) < 1,, VLOOKUP(B$1 & "," & $A2, {Field!$C$2:$C593,Field!$F$2:$F593}, 2, FALSE) = "",, TRUE, VLOOKUP(VLOOKUP(B$1 & "," & $A2, {Field!$C$2:$C593,Field!$F$2:$F593}, 2, FALSE), {DataIDs, DataIcons}, 2, FALSE) )} | D21: {=IFS( COUNTIF(Field!$C$2:$C593, D$1 & "," & $A2) < 1,, VLOOKUP(D$1 & "," & $A2, {Field!$C$2:$C593,Field!$F$2:$F593}, 2, FALSE) = "",, TRUE, VLOOKUP(VLOOKUP(D$1 & "," & $A2, {Field!$C$2:$C593,Field!$F$2:$F593}, 2, FALSE), {DataIDs, DataIcons}, 2, FALSE) )} | F21: {=IFS( COUNTIF(Field!$C$2:$C593, F$1 & "," & $A2) < 1,, VLOOKUP(F$1 & "," & $A2, {Field!$C$2:$C593,Field!$F$2:$F593}, 2, FALSE) = "",, TRUE, VLOOKUP(VLOOKUP(F$1 & "," & $A2, {Field!$C$2:$C593,Field!$F$2:$F593}, 2, FALSE), {DataIDs, DataIcons}, 2, FALSE) )} | H21: {=IFS( COUNTIF(Field!$C$2:$C593, H$1 & "," & $A2) < 1,, VLOOKUP(H$1 & "," & $A2, {Field!$C$2:$C593,Field!$F$2:$F593}, 2, FALSE) = "",, TRUE, VLOOKUP(VLOOKUP(H$1 & "," & $A2, {Field!$C$2:$C593,Field!$F$2:$F593}, 2, FALSE), {DataIDs, DataIcons}, 2, FALSE) )} | J21: {=IFS( COUNTIF(Field!$C$2:$C593, J$1 & "," & $A2) < 1,, VLOOKUP(J$1 & "," & $A2, {Field!$C$2:$C593,Field!$F$2:$F593}, 2, FALSE) = "",, TRUE, VLOOKUP(VLOOKUP(J$1 & "," & $A2, {Field!$C$2:$C593,Field!$F$2:$F593}, 2, FALSE), {DataIDs, DataIcons}, 2, FALSE) )} -> #N/A | L21: {=IFS( COUNTIF(Field!$C$2:$C593, L$1 & "," & $A2) < 1,, VLOOKUP(L$1 & "," & $A2, {Field!$C$2:$C593,Field!$F$2:$F593}, 2, FALSE) = "",, TRUE, VLOOKUP(VLOOKUP(L$1 & "," & $A2, {Field!$C$2:$C593,Field!$F$2:$F593}, 2, FALSE), {DataIDs, DataIcons}, 2, FALSE) )} | N21: {=IFS( COUNTIF(Field!$C$2:$C593, N$1 & "," & $A2) < 1,, VLOOKUP(N$1 & "," & $A2, {Field!$C$2:$C593,Field!$F$2:$F593}, 2, FALSE) = "",, TRUE, VLOOKUP(VLOOKUP(N$1 & "," & $A2, {Field!$C$2:$C593,Field!$F$2:$F593}, 2, FALSE), {DataIDs, DataIcons}, 2, FALSE) )} | P21: {=IFS( COUNTIF(Field!$C$2:$C593, P$1 & "," & $A2) < 1,, VLOOKUP(P$1 & "," & $A2, {Field!$C$2:$C593,Field!$F$2:$F593}, 2, FALSE) = "",, TRUE, VLOOKUP(VLOOKUP(P$1 & "," & $A2, {Field!$C$2:$C593,Field!$F$2:$F593}, 2, FALSE), {DataIDs, DataIcons}, 2, FALSE) )} | R21: {=IFS( COUNTIF(Field!$C$2:$C593, R$1 & "," & $A2) < 1,, VLOOKUP(R$1 & "," & $A2, {Field!$C$2:$C593,Field!$F$2:$F593}, 2, FALSE) = "",, TRUE, VLOOKUP(VLOOKUP(R$1 & "," & $A2, {Field!$C$2:$C593,Field!$F$2:$F593}, 2, FALSE), {DataIDs, DataIcons}, 2, FALSE) )} | W21: TRUE | X21: =IF(W21, "💀",) -> 💀 | Y21: Closed | AA21: FALSE | AB21: =IF(AA21, "💀",) | AC21: Closed | AE21: FALSE | AF21: =IF(AE21, "💀",) | AG21: Closed | AI21: TRUE | AJ21: =IF(AI21, "💀",) -> 💀 | AK21: Closed | AM21: FALSE | AN21: =IF(AM21, "💀",) | AO21: Closed | AQ21: TRUE | AR21: =IF(AQ21, "💀",) -> 💀 | AS21: Closed | AU21: FALSE | AV21: =IF(AU21, "💀",) | AW21: Closed | AY21: TRUE | AZ21: =IF(AY21, "💀",) -> 💀 | BA21: Closed | BC21: TRUE | BD21: =IF(BC21, "💀",) -> 💀 | BE21: Closed | BJ21: generator_RD_04 | BK21: =BH21
V22: 6 | W22: =$BJ$13 -> chain_B_01 | Z22: {=IFS( ISBLANK(W22),, COUNTIF(DataIDs, W22) < 1, "❌", TRUE, VLOOKUP(W22, {DataIDs, DataIcons}, 2, FALSE) )} | AA22: chain_A_03 | AD22: {=IFS( ISBLANK(AA22),, COUNTIF(DataIDs, AA22) < 1, "❌", TRUE, VLOOKUP(AA22, {DataIDs, DataIcons}, 2, FALSE) )} | AE22: chain_A_02 | AH22: {=IFS( ISBLANK(AE22),, COUNTIF(DataIDs, AE22) < 1, "❌", TRUE, VLOOKUP(AE22, {DataIDs, DataIcons}, 2, FALSE) )} | AL22: {=IFS( ISBLANK(AI22),, COUNTIF(DataIDs, AI22) < 1, "❌", TRUE, VLOOKUP(AI22, {DataIDs, DataIcons}, 2, FALSE) )} | AP22: {=IFS( ISBLANK(AM22),, COUNTIF(DataIDs, AM22) < 1, "❌", TRUE, VLOOKUP(AM22, {DataIDs, DataIcons}, 2, FALSE) )} | AT22: {=IFS( ISBLANK(AQ22),, COUNTIF(DataIDs, AQ22) < 1, "❌", TRUE, VLOOKUP(AQ22, {DataIDs, DataIcons}, 2, FALSE) )} | AU22: chain_A_02 | AX22: {=IFS( ISBLANK(AU22),, COUNTIF(DataIDs, AU22) < 1, "❌", TRUE, VLOOKUP(AU22, {DataIDs, DataIcons}, 2, FALSE) )} | AY22: =$BJ$13 -> chain_B_01 | BB22: {=IFS( ISBLANK(AY22),, COUNTIF(DataIDs, AY22) < 1, "❌", TRUE, VLOOKUP(AY22, {DataIDs, DataIcons}, 2, FALSE) )} | BC22: chain_B_03 | BF22: {=IFS( ISBLANK(BC22),, COUNTIF(DataIDs, BC22) < 1, "❌", TRUE, VLOOKUP(BC22, {DataIDs, DataIcons}, 2, FALSE) )} | BJ22: generator_RD_05
